[2021-09-28 10:40:33 +0000] [669] [INFO] Starting gunicorn 20.0.4
[2021-09-28 10:40:33 +0000] [669] [INFO] Listening at: http://0.0.0.0:8000 (669)
[2021-09-28 10:40:33 +0000] [669] [INFO] Using worker: threads
[2021-09-28 10:40:33 +0000] [672] [INFO] Booting worker with pid: 672
Mysql closed the connection. Perform reconnect...
Connection was already closed.
/usr/local/lib/python3.6/site-packages/apscheduler/schedulers/base.py:162: RuntimeWarning: Got OperationalError: (2003, "Can't connect to MySQL server on 'crm.123medhk.com' ([Errno 111] Connection refused)"). Please, check that you have migrated the database via python manage.py migrate
  self._real_add_job(job, jobstore_alias, replace_existing)
Exception during getting jobs
Traceback (most recent call last):
  File "/usr/local/lib/python3.6/site-packages/pymysql/connections.py", line 583, in connect
    **kwargs)
  File "/usr/local/lib/python3.6/socket.py", line 724, in create_connection
    raise err
  File "/usr/local/lib/python3.6/socket.py", line 713, in create_connection
    sock.connect(sa)
ConnectionRefusedError: [Errno 111] Connection refused

During handling of the above exception, another exception occurred:

Traceback (most recent call last):
  File "/usr/local/lib/python3.6/site-packages/django/db/backends/base/base.py", line 217, in ensure_connection
    self.connect()
  File "/usr/local/lib/python3.6/site-packages/django/db/backends/base/base.py", line 195, in connect
    self.connection = self.get_new_connection(conn_params)
  File "/usr/local/lib/python3.6/site-packages/django/db/backends/mysql/base.py", line 227, in get_new_connection
    return Database.connect(**conn_params)
  File "/usr/local/lib/python3.6/site-packages/pymysql/__init__.py", line 94, in Connect
    return Connection(*args, **kwargs)
  File "/usr/local/lib/python3.6/site-packages/pymysql/connections.py", line 325, in __init__
    self.connect()
  File "/usr/local/lib/python3.6/site-packages/pymysql/connections.py", line 630, in connect
    raise exc
pymysql.err.OperationalError: (2003, "Can't connect to MySQL server on 'crm.123medhk.com' ([Errno 111] Connection refused)")

The above exception was the direct cause of the following exception:

Traceback (most recent call last):
  File "/usr/local/lib/python3.6/site-packages/django_apscheduler/jobstores.py", line 68, in get_due_jobs
    out = self._get_jobs(next_run_time__lte=serialize_dt(now))
  File "/usr/local/lib/python3.6/site-packages/django_apscheduler/jobstores.py", line 153, in _get_jobs
    for job_id, job_state in job_states:
  File "/usr/local/lib/python3.6/site-packages/django/db/models/query.py", line 274, in __iter__
    self._fetch_all()
  File "/usr/local/lib/python3.6/site-packages/django/db/models/query.py", line 1242, in _fetch_all
    self._result_cache = list(self._iterable_class(self))
  File "/usr/local/lib/python3.6/site-packages/django/db/models/query.py", line 144, in __iter__
    return compiler.results_iter(tuple_expected=True, chunked_fetch=self.chunked_fetch, chunk_size=self.chunk_size)
  File "/usr/local/lib/python3.6/site-packages/django/db/models/sql/compiler.py", line 1052, in results_iter
    results = self.execute_sql(MULTI, chunked_fetch=chunked_fetch, chunk_size=chunk_size)
  File "/usr/local/lib/python3.6/site-packages/django/db/models/sql/compiler.py", line 1098, in execute_sql
    cursor = self.connection.cursor()
  File "/usr/local/lib/python3.6/site-packages/django/db/backends/base/base.py", line 256, in cursor
    return self._cursor()
  File "/usr/local/lib/python3.6/site-packages/django/db/backends/base/base.py", line 233, in _cursor
    self.ensure_connection()
  File "/usr/local/lib/python3.6/site-packages/django/db/backends/base/base.py", line 217, in ensure_connection
    self.connect()
  File "/usr/local/lib/python3.6/site-packages/django/db/utils.py", line 89, in __exit__
    raise dj_exc_value.with_traceback(traceback) from exc_value
  File "/usr/local/lib/python3.6/site-packages/django/db/backends/base/base.py", line 217, in ensure_connection
    self.connect()
  File "/usr/local/lib/python3.6/site-packages/django/db/backends/base/base.py", line 195, in connect
    self.connection = self.get_new_connection(conn_params)
  File "/usr/local/lib/python3.6/site-packages/django/db/backends/mysql/base.py", line 227, in get_new_connection
    return Database.connect(**conn_params)
  File "/usr/local/lib/python3.6/site-packages/pymysql/__init__.py", line 94, in Connect
    return Connection(*args, **kwargs)
  File "/usr/local/lib/python3.6/site-packages/pymysql/connections.py", line 325, in __init__
    self.connect()
  File "/usr/local/lib/python3.6/site-packages/pymysql/connections.py", line 630, in connect
    raise exc
django.db.utils.OperationalError: (2003, "Can't connect to MySQL server on 'crm.123medhk.com' ([Errno 111] Connection refused)")
Exception during get_next_run_time for jobs
Traceback (most recent call last):
  File "/usr/local/lib/python3.6/site-packages/pymysql/connections.py", line 583, in connect
    **kwargs)
  File "/usr/local/lib/python3.6/socket.py", line 724, in create_connection
    raise err
  File "/usr/local/lib/python3.6/socket.py", line 713, in create_connection
    sock.connect(sa)
ConnectionRefusedError: [Errno 111] Connection refused

During handling of the above exception, another exception occurred:

Traceback (most recent call last):
  File "/usr/local/lib/python3.6/site-packages/django/db/backends/base/base.py", line 217, in ensure_connection
    self.connect()
  File "/usr/local/lib/python3.6/site-packages/django/db/backends/base/base.py", line 195, in connect
    self.connection = self.get_new_connection(conn_params)
  File "/usr/local/lib/python3.6/site-packages/django/db/backends/mysql/base.py", line 227, in get_new_connection
    return Database.connect(**conn_params)
  File "/usr/local/lib/python3.6/site-packages/pymysql/__init__.py", line 94, in Connect
    return Connection(*args, **kwargs)
  File "/usr/local/lib/python3.6/site-packages/pymysql/connections.py", line 325, in __init__
    self.connect()
  File "/usr/local/lib/python3.6/site-packages/pymysql/connections.py", line 630, in connect
    raise exc
pymysql.err.OperationalError: (2003, "Can't connect to MySQL server on 'crm.123medhk.com' ([Errno 111] Connection refused)")

The above exception was the direct cause of the following exception:

Traceback (most recent call last):
  File "/usr/local/lib/python3.6/site-packages/django_apscheduler/jobstores.py", line 78, in get_next_run_time
    return deserialize_dt(DjangoJob.objects.filter(next_run_time__isnull=False).earliest('next_run_time').next_run_time)
  File "/usr/local/lib/python3.6/site-packages/django/db/models/query.py", line 646, in earliest
    return self._earliest(*fields, field_name=field_name)
  File "/usr/local/lib/python3.6/site-packages/django/db/models/query.py", line 643, in _earliest
    return obj.get()
  File "/usr/local/lib/python3.6/site-packages/django/db/models/query.py", line 402, in get
    num = len(clone)
  File "/usr/local/lib/python3.6/site-packages/django/db/models/query.py", line 256, in __len__
    self._fetch_all()
  File "/usr/local/lib/python3.6/site-packages/django/db/models/query.py", line 1242, in _fetch_all
    self._result_cache = list(self._iterable_class(self))
  File "/usr/local/lib/python3.6/site-packages/django/db/models/query.py", line 55, in __iter__
    results = compiler.execute_sql(chunked_fetch=self.chunked_fetch, chunk_size=self.chunk_size)
  File "/usr/local/lib/python3.6/site-packages/django/db/models/sql/compiler.py", line 1098, in execute_sql
    cursor = self.connection.cursor()
  File "/usr/local/lib/python3.6/site-packages/django/db/backends/base/base.py", line 256, in cursor
    return self._cursor()
  File "/usr/local/lib/python3.6/site-packages/django/db/backends/base/base.py", line 233, in _cursor
    self.ensure_connection()
  File "/usr/local/lib/python3.6/site-packages/django/db/backends/base/base.py", line 217, in ensure_connection
    self.connect()
  File "/usr/local/lib/python3.6/site-packages/django/db/utils.py", line 89, in __exit__
    raise dj_exc_value.with_traceback(traceback) from exc_value
  File "/usr/local/lib/python3.6/site-packages/django/db/backends/base/base.py", line 217, in ensure_connection
    self.connect()
  File "/usr/local/lib/python3.6/site-packages/django/db/backends/base/base.py", line 195, in connect
    self.connection = self.get_new_connection(conn_params)
  File "/usr/local/lib/python3.6/site-packages/django/db/backends/mysql/base.py", line 227, in get_new_connection
    return Database.connect(**conn_params)
  File "/usr/local/lib/python3.6/site-packages/pymysql/__init__.py", line 94, in Connect
    return Connection(*args, **kwargs)
  File "/usr/local/lib/python3.6/site-packages/pymysql/connections.py", line 325, in __init__
    self.connect()
  File "/usr/local/lib/python3.6/site-packages/pymysql/connections.py", line 630, in connect
    raise exc
django.db.utils.OperationalError: (2003, "Can't connect to MySQL server on 'crm.123medhk.com' ([Errno 111] Connection refused)")
Internal Server Error: /admin/Record/everytask/11218/change/
Traceback (most recent call last):
  File "/usr/local/lib/python3.6/site-packages/django/contrib/sessions/backends/base.py", line 189, in _get_session
    return self._session_cache
AttributeError: 'SessionStore' object has no attribute '_session_cache'

During handling of the above exception, another exception occurred:

Traceback (most recent call last):
  File "/usr/local/lib/python3.6/site-packages/pymysql/connections.py", line 583, in connect
    **kwargs)
  File "/usr/local/lib/python3.6/socket.py", line 724, in create_connection
    raise err
  File "/usr/local/lib/python3.6/socket.py", line 713, in create_connection
    sock.connect(sa)
ConnectionRefusedError: [Errno 111] Connection refused

During handling of the above exception, another exception occurred:

Traceback (most recent call last):
  File "/usr/local/lib/python3.6/site-packages/django/db/backends/base/base.py", line 217, in ensure_connection
    self.connect()
  File "/usr/local/lib/python3.6/site-packages/django/db/backends/base/base.py", line 195, in connect
    self.connection = self.get_new_connection(conn_params)
  File "/usr/local/lib/python3.6/site-packages/django/db/backends/mysql/base.py", line 227, in get_new_connection
    return Database.connect(**conn_params)
  File "/usr/local/lib/python3.6/site-packages/pymysql/__init__.py", line 94, in Connect
    return Connection(*args, **kwargs)
  File "/usr/local/lib/python3.6/site-packages/pymysql/connections.py", line 325, in __init__
    self.connect()
  File "/usr/local/lib/python3.6/site-packages/pymysql/connections.py", line 630, in connect
    raise exc
pymysql.err.OperationalError: (2003, "Can't connect to MySQL server on 'crm.123medhk.com' ([Errno 111] Connection refused)")

The above exception was the direct cause of the following exception:

Traceback (most recent call last):
  File "/usr/local/lib/python3.6/site-packages/django/core/handlers/exception.py", line 34, in inner
    response = get_response(request)
  File "/usr/local/lib/python3.6/site-packages/django/core/handlers/base.py", line 115, in _get_response
    response = self.process_exception_by_middleware(e, request)
  File "/usr/local/lib/python3.6/site-packages/django/core/handlers/base.py", line 113, in _get_response
    response = wrapped_callback(request, *callback_args, **callback_kwargs)
  File "/usr/local/lib/python3.6/site-packages/django/contrib/admin/options.py", line 606, in wrapper
    return self.admin_site.admin_view(view)(*args, **kwargs)
  File "/usr/local/lib/python3.6/site-packages/django/utils/decorators.py", line 142, in _wrapped_view
    response = view_func(request, *args, **kwargs)
  File "/usr/local/lib/python3.6/site-packages/django/views/decorators/cache.py", line 44, in _wrapped_view_func
    response = view_func(request, *args, **kwargs)
  File "/usr/local/lib/python3.6/site-packages/django/contrib/admin/sites.py", line 212, in inner
    if not self.has_permission(request):
  File "/usr/local/lib/python3.6/site-packages/django/contrib/admin/sites.py", line 186, in has_permission
    return request.user.is_active and request.user.is_staff
  File "/usr/local/lib/python3.6/site-packages/django/utils/functional.py", line 256, in inner
    self._setup()
  File "/usr/local/lib/python3.6/site-packages/django/utils/functional.py", line 392, in _setup
    self._wrapped = self._setupfunc()
  File "/usr/local/lib/python3.6/site-packages/django/contrib/auth/middleware.py", line 24, in <lambda>
    request.user = SimpleLazyObject(lambda: get_user(request))
  File "/usr/local/lib/python3.6/site-packages/django/contrib/auth/middleware.py", line 12, in get_user
    request._cached_user = auth.get_user(request)
  File "/usr/local/lib/python3.6/site-packages/django/contrib/auth/__init__.py", line 182, in get_user
    user_id = _get_user_session_key(request)
  File "/usr/local/lib/python3.6/site-packages/django/contrib/auth/__init__.py", line 59, in _get_user_session_key
    return get_user_model()._meta.pk.to_python(request.session[SESSION_KEY])
  File "/usr/local/lib/python3.6/site-packages/django/contrib/sessions/backends/base.py", line 54, in __getitem__
    return self._session[key]
  File "/usr/local/lib/python3.6/site-packages/django/contrib/sessions/backends/base.py", line 194, in _get_session
    self._session_cache = self.load()
  File "/usr/local/lib/python3.6/site-packages/django/contrib/sessions/backends/db.py", line 43, in load
    s = self._get_session_from_db()
  File "/usr/local/lib/python3.6/site-packages/django/contrib/sessions/backends/db.py", line 34, in _get_session_from_db
    expire_date__gt=timezone.now()
  File "/usr/local/lib/python3.6/site-packages/django/db/models/manager.py", line 82, in manager_method
    return getattr(self.get_queryset(), name)(*args, **kwargs)
  File "/usr/local/lib/python3.6/site-packages/django/db/models/query.py", line 402, in get
    num = len(clone)
  File "/usr/local/lib/python3.6/site-packages/django/db/models/query.py", line 256, in __len__
    self._fetch_all()
  File "/usr/local/lib/python3.6/site-packages/django/db/models/query.py", line 1242, in _fetch_all
    self._result_cache = list(self._iterable_class(self))
  File "/usr/local/lib/python3.6/site-packages/django/db/models/query.py", line 55, in __iter__
    results = compiler.execute_sql(chunked_fetch=self.chunked_fetch, chunk_size=self.chunk_size)
  File "/usr/local/lib/python3.6/site-packages/django/db/models/sql/compiler.py", line 1098, in execute_sql
    cursor = self.connection.cursor()
  File "/usr/local/lib/python3.6/site-packages/django/db/backends/base/base.py", line 256, in cursor
    return self._cursor()
  File "/usr/local/lib/python3.6/site-packages/django/db/backends/base/base.py", line 233, in _cursor
    self.ensure_connection()
  File "/usr/local/lib/python3.6/site-packages/django/db/backends/base/base.py", line 217, in ensure_connection
    self.connect()
  File "/usr/local/lib/python3.6/site-packages/django/db/utils.py", line 89, in __exit__
    raise dj_exc_value.with_traceback(traceback) from exc_value
  File "/usr/local/lib/python3.6/site-packages/django/db/backends/base/base.py", line 217, in ensure_connection
    self.connect()
  File "/usr/local/lib/python3.6/site-packages/django/db/backends/base/base.py", line 195, in connect
    self.connection = self.get_new_connection(conn_params)
  File "/usr/local/lib/python3.6/site-packages/django/db/backends/mysql/base.py", line 227, in get_new_connection
    return Database.connect(**conn_params)
  File "/usr/local/lib/python3.6/site-packages/pymysql/__init__.py", line 94, in Connect
    return Connection(*args, **kwargs)
  File "/usr/local/lib/python3.6/site-packages/pymysql/connections.py", line 325, in __init__
    self.connect()
  File "/usr/local/lib/python3.6/site-packages/pymysql/connections.py", line 630, in connect
    raise exc
django.db.utils.OperationalError: (2003, "Can't connect to MySQL server on 'crm.123medhk.com' ([Errno 111] Connection refused)")
Internal Server Error: /admin/Record/everytask/11219/change/
Traceback (most recent call last):
  File "/usr/local/lib/python3.6/site-packages/django/contrib/sessions/backends/base.py", line 189, in _get_session
    return self._session_cache
AttributeError: 'SessionStore' object has no attribute '_session_cache'

During handling of the above exception, another exception occurred:

Traceback (most recent call last):
  File "/usr/local/lib/python3.6/site-packages/pymysql/connections.py", line 583, in connect
    **kwargs)
  File "/usr/local/lib/python3.6/socket.py", line 724, in create_connection
    raise err
  File "/usr/local/lib/python3.6/socket.py", line 713, in create_connection
    sock.connect(sa)
ConnectionRefusedError: [Errno 111] Connection refused

During handling of the above exception, another exception occurred:

Traceback (most recent call last):
  File "/usr/local/lib/python3.6/site-packages/django/db/backends/base/base.py", line 217, in ensure_connection
    self.connect()
  File "/usr/local/lib/python3.6/site-packages/django/db/backends/base/base.py", line 195, in connect
    self.connection = self.get_new_connection(conn_params)
  File "/usr/local/lib/python3.6/site-packages/django/db/backends/mysql/base.py", line 227, in get_new_connection
    return Database.connect(**conn_params)
  File "/usr/local/lib/python3.6/site-packages/pymysql/__init__.py", line 94, in Connect
    return Connection(*args, **kwargs)
  File "/usr/local/lib/python3.6/site-packages/pymysql/connections.py", line 325, in __init__
    self.connect()
  File "/usr/local/lib/python3.6/site-packages/pymysql/connections.py", line 630, in connect
    raise exc
pymysql.err.OperationalError: (2003, "Can't connect to MySQL server on 'crm.123medhk.com' ([Errno 111] Connection refused)")

The above exception was the direct cause of the following exception:

Traceback (most recent call last):
  File "/usr/local/lib/python3.6/site-packages/django/core/handlers/exception.py", line 34, in inner
    response = get_response(request)
  File "/usr/local/lib/python3.6/site-packages/django/core/handlers/base.py", line 115, in _get_response
    response = self.process_exception_by_middleware(e, request)
  File "/usr/local/lib/python3.6/site-packages/django/core/handlers/base.py", line 113, in _get_response
    response = wrapped_callback(request, *callback_args, **callback_kwargs)
  File "/usr/local/lib/python3.6/site-packages/django/contrib/admin/options.py", line 606, in wrapper
    return self.admin_site.admin_view(view)(*args, **kwargs)
  File "/usr/local/lib/python3.6/site-packages/django/utils/decorators.py", line 142, in _wrapped_view
    response = view_func(request, *args, **kwargs)
  File "/usr/local/lib/python3.6/site-packages/django/views/decorators/cache.py", line 44, in _wrapped_view_func
    response = view_func(request, *args, **kwargs)
  File "/usr/local/lib/python3.6/site-packages/django/contrib/admin/sites.py", line 212, in inner
    if not self.has_permission(request):
  File "/usr/local/lib/python3.6/site-packages/django/contrib/admin/sites.py", line 186, in has_permission
    return request.user.is_active and request.user.is_staff
  File "/usr/local/lib/python3.6/site-packages/django/utils/functional.py", line 256, in inner
    self._setup()
  File "/usr/local/lib/python3.6/site-packages/django/utils/functional.py", line 392, in _setup
    self._wrapped = self._setupfunc()
  File "/usr/local/lib/python3.6/site-packages/django/contrib/auth/middleware.py", line 24, in <lambda>
    request.user = SimpleLazyObject(lambda: get_user(request))
  File "/usr/local/lib/python3.6/site-packages/django/contrib/auth/middleware.py", line 12, in get_user
    request._cached_user = auth.get_user(request)
  File "/usr/local/lib/python3.6/site-packages/django/contrib/auth/__init__.py", line 182, in get_user
    user_id = _get_user_session_key(request)
  File "/usr/local/lib/python3.6/site-packages/django/contrib/auth/__init__.py", line 59, in _get_user_session_key
    return get_user_model()._meta.pk.to_python(request.session[SESSION_KEY])
  File "/usr/local/lib/python3.6/site-packages/django/contrib/sessions/backends/base.py", line 54, in __getitem__
    return self._session[key]
  File "/usr/local/lib/python3.6/site-packages/django/contrib/sessions/backends/base.py", line 194, in _get_session
    self._session_cache = self.load()
  File "/usr/local/lib/python3.6/site-packages/django/contrib/sessions/backends/db.py", line 43, in load
    s = self._get_session_from_db()
  File "/usr/local/lib/python3.6/site-packages/django/contrib/sessions/backends/db.py", line 34, in _get_session_from_db
    expire_date__gt=timezone.now()
  File "/usr/local/lib/python3.6/site-packages/django/db/models/manager.py", line 82, in manager_method
    return getattr(self.get_queryset(), name)(*args, **kwargs)
  File "/usr/local/lib/python3.6/site-packages/django/db/models/query.py", line 402, in get
    num = len(clone)
  File "/usr/local/lib/python3.6/site-packages/django/db/models/query.py", line 256, in __len__
    self._fetch_all()
  File "/usr/local/lib/python3.6/site-packages/django/db/models/query.py", line 1242, in _fetch_all
    self._result_cache = list(self._iterable_class(self))
  File "/usr/local/lib/python3.6/site-packages/django/db/models/query.py", line 55, in __iter__
    results = compiler.execute_sql(chunked_fetch=self.chunked_fetch, chunk_size=self.chunk_size)
  File "/usr/local/lib/python3.6/site-packages/django/db/models/sql/compiler.py", line 1098, in execute_sql
    cursor = self.connection.cursor()
  File "/usr/local/lib/python3.6/site-packages/django/db/backends/base/base.py", line 256, in cursor
    return self._cursor()
  File "/usr/local/lib/python3.6/site-packages/django/db/backends/base/base.py", line 233, in _cursor
    self.ensure_connection()
  File "/usr/local/lib/python3.6/site-packages/django/db/backends/base/base.py", line 217, in ensure_connection
    self.connect()
  File "/usr/local/lib/python3.6/site-packages/django/db/utils.py", line 89, in __exit__
    raise dj_exc_value.with_traceback(traceback) from exc_value
  File "/usr/local/lib/python3.6/site-packages/django/db/backends/base/base.py", line 217, in ensure_connection
    self.connect()
  File "/usr/local/lib/python3.6/site-packages/django/db/backends/base/base.py", line 195, in connect
    self.connection = self.get_new_connection(conn_params)
  File "/usr/local/lib/python3.6/site-packages/django/db/backends/mysql/base.py", line 227, in get_new_connection
    return Database.connect(**conn_params)
  File "/usr/local/lib/python3.6/site-packages/pymysql/__init__.py", line 94, in Connect
    return Connection(*args, **kwargs)
  File "/usr/local/lib/python3.6/site-packages/pymysql/connections.py", line 325, in __init__
    self.connect()
  File "/usr/local/lib/python3.6/site-packages/pymysql/connections.py", line 630, in connect
    raise exc
django.db.utils.OperationalError: (2003, "Can't connect to MySQL server on 'crm.123medhk.com' ([Errno 111] Connection refused)")
[2021-09-28 11:08:39 +0000] [669] [INFO] Handling signal: term
[2021-09-28 19:08:39 +0800] [672] [INFO] Worker exiting (pid: 672)
[2021-09-28 11:08:39 +0000] [669] [INFO] Shutting down: Master
[2021-09-28 11:08:54 +0000] [668] [INFO] Starting gunicorn 20.0.4
[2021-09-28 11:08:54 +0000] [668] [INFO] Listening at: http://0.0.0.0:8000 (668)
[2021-09-28 11:08:54 +0000] [668] [INFO] Using worker: threads
[2021-09-28 11:08:54 +0000] [671] [INFO] Booting worker with pid: 671
[2021-09-28 11:19:51 +0000] [668] [INFO] Handling signal: term
/usr/local/lib/python3.6/site-packages/django/db/models/fields/__init__.py:1365: RuntimeWarning: DateTimeField EveryTask.send_finish_time received a naive datetime (2021-09-26 00:00:00) while time zone support is active.
  RuntimeWarning)
/usr/local/lib/python3.6/site-packages/django/db/models/fields/__init__.py:1365: RuntimeWarning: DateTimeField EveryTask.send_finish_time received a naive datetime (2021-09-29 00:00:00) while time zone support is active.
  RuntimeWarning)
/usr/local/lib/python3.6/site-packages/django/db/models/fields/__init__.py:1423: RuntimeWarning: DateTimeField EveryTask.send_finish_time received a naive datetime (2021-09-28 19:10:19.145432) while time zone support is active.
  RuntimeWarning)
/usr/local/lib/python3.6/site-packages/django/db/models/fields/__init__.py:1423: RuntimeWarning: DateTimeField EveryTask.send_finish_time received a naive datetime (2021-09-28 19:10:20.446927) while time zone support is active.
  RuntimeWarning)
/usr/local/lib/python3.6/site-packages/django/db/models/fields/__init__.py:1365: RuntimeWarning: DateTimeField EmailApply.next_time received a naive datetime (2021-09-27 00:00:00) while time zone support is active.
  RuntimeWarning)
/usr/local/lib/python3.6/site-packages/django/db/models/fields/__init__.py:1365: RuntimeWarning: DateTimeField EmailApply.next_time received a naive datetime (2021-09-28 00:00:00) while time zone support is active.
  RuntimeWarning)
/usr/local/lib/python3.6/site-packages/django/db/models/fields/__init__.py:1423: RuntimeWarning: DateTimeField EveryTask.send_finish_time received a naive datetime (2021-09-28 19:15:18.752745) while time zone support is active.
  RuntimeWarning)
[2021-09-28 19:19:51 +0800] [671] [INFO] Worker exiting (pid: 671)
[2021-09-28 11:19:51 +0000] [668] [INFO] Shutting down: Master
[2021-09-28 11:20:03 +0000] [667] [INFO] Starting gunicorn 20.0.4
[2021-09-28 11:20:03 +0000] [667] [INFO] Listening at: http://0.0.0.0:8000 (667)
[2021-09-28 11:20:03 +0000] [667] [INFO] Using worker: threads
[2021-09-28 11:20:03 +0000] [670] [INFO] Booting worker with pid: 670
Internal Server Error: /admin/Record/everytask/11219/change/
Traceback (most recent call last):
  File "/usr/local/lib/python3.6/site-packages/django/contrib/sessions/backends/base.py", line 189, in _get_session
    return self._session_cache
AttributeError: 'SessionStore' object has no attribute '_session_cache'

During handling of the above exception, another exception occurred:

Traceback (most recent call last):
  File "/usr/local/lib/python3.6/site-packages/pymysql/connections.py", line 583, in connect
    **kwargs)
  File "/usr/local/lib/python3.6/socket.py", line 724, in create_connection
    raise err
  File "/usr/local/lib/python3.6/socket.py", line 713, in create_connection
    sock.connect(sa)
ConnectionRefusedError: [Errno 111] Connection refused

During handling of the above exception, another exception occurred:

Traceback (most recent call last):
  File "/usr/local/lib/python3.6/site-packages/django/db/backends/base/base.py", line 217, in ensure_connection
    self.connect()
  File "/usr/local/lib/python3.6/site-packages/django/db/backends/base/base.py", line 195, in connect
    self.connection = self.get_new_connection(conn_params)
  File "/usr/local/lib/python3.6/site-packages/django/db/backends/mysql/base.py", line 227, in get_new_connection
    return Database.connect(**conn_params)
  File "/usr/local/lib/python3.6/site-packages/pymysql/__init__.py", line 94, in Connect
    return Connection(*args, **kwargs)
  File "/usr/local/lib/python3.6/site-packages/pymysql/connections.py", line 325, in __init__
    self.connect()
  File "/usr/local/lib/python3.6/site-packages/pymysql/connections.py", line 630, in connect
    raise exc
pymysql.err.OperationalError: (2003, "Can't connect to MySQL server on 'crm.123medhk.com' ([Errno 111] Connection refused)")

The above exception was the direct cause of the following exception:

Traceback (most recent call last):
  File "/usr/local/lib/python3.6/site-packages/django/core/handlers/exception.py", line 34, in inner
    response = get_response(request)
  File "/usr/local/lib/python3.6/site-packages/django/core/handlers/base.py", line 115, in _get_response
    response = self.process_exception_by_middleware(e, request)
  File "/usr/local/lib/python3.6/site-packages/django/core/handlers/base.py", line 113, in _get_response
    response = wrapped_callback(request, *callback_args, **callback_kwargs)
  File "/usr/local/lib/python3.6/site-packages/django/contrib/admin/options.py", line 606, in wrapper
    return self.admin_site.admin_view(view)(*args, **kwargs)
  File "/usr/local/lib/python3.6/site-packages/django/utils/decorators.py", line 142, in _wrapped_view
    response = view_func(request, *args, **kwargs)
  File "/usr/local/lib/python3.6/site-packages/django/views/decorators/cache.py", line 44, in _wrapped_view_func
    response = view_func(request, *args, **kwargs)
  File "/usr/local/lib/python3.6/site-packages/django/contrib/admin/sites.py", line 212, in inner
    if not self.has_permission(request):
  File "/usr/local/lib/python3.6/site-packages/django/contrib/admin/sites.py", line 186, in has_permission
    return request.user.is_active and request.user.is_staff
  File "/usr/local/lib/python3.6/site-packages/django/utils/functional.py", line 256, in inner
    self._setup()
  File "/usr/local/lib/python3.6/site-packages/django/utils/functional.py", line 392, in _setup
    self._wrapped = self._setupfunc()
  File "/usr/local/lib/python3.6/site-packages/django/contrib/auth/middleware.py", line 24, in <lambda>
    request.user = SimpleLazyObject(lambda: get_user(request))
  File "/usr/local/lib/python3.6/site-packages/django/contrib/auth/middleware.py", line 12, in get_user
    request._cached_user = auth.get_user(request)
  File "/usr/local/lib/python3.6/site-packages/django/contrib/auth/__init__.py", line 182, in get_user
    user_id = _get_user_session_key(request)
  File "/usr/local/lib/python3.6/site-packages/django/contrib/auth/__init__.py", line 59, in _get_user_session_key
    return get_user_model()._meta.pk.to_python(request.session[SESSION_KEY])
  File "/usr/local/lib/python3.6/site-packages/django/contrib/sessions/backends/base.py", line 54, in __getitem__
    return self._session[key]
  File "/usr/local/lib/python3.6/site-packages/django/contrib/sessions/backends/base.py", line 194, in _get_session
    self._session_cache = self.load()
  File "/usr/local/lib/python3.6/site-packages/django/contrib/sessions/backends/db.py", line 43, in load
    s = self._get_session_from_db()
  File "/usr/local/lib/python3.6/site-packages/django/contrib/sessions/backends/db.py", line 34, in _get_session_from_db
    expire_date__gt=timezone.now()
  File "/usr/local/lib/python3.6/site-packages/django/db/models/manager.py", line 82, in manager_method
    return getattr(self.get_queryset(), name)(*args, **kwargs)
  File "/usr/local/lib/python3.6/site-packages/django/db/models/query.py", line 402, in get
    num = len(clone)
  File "/usr/local/lib/python3.6/site-packages/django/db/models/query.py", line 256, in __len__
    self._fetch_all()
  File "/usr/local/lib/python3.6/site-packages/django/db/models/query.py", line 1242, in _fetch_all
    self._result_cache = list(self._iterable_class(self))
  File "/usr/local/lib/python3.6/site-packages/django/db/models/query.py", line 55, in __iter__
    results = compiler.execute_sql(chunked_fetch=self.chunked_fetch, chunk_size=self.chunk_size)
  File "/usr/local/lib/python3.6/site-packages/django/db/models/sql/compiler.py", line 1098, in execute_sql
    cursor = self.connection.cursor()
  File "/usr/local/lib/python3.6/site-packages/django/db/backends/base/base.py", line 256, in cursor
    return self._cursor()
  File "/usr/local/lib/python3.6/site-packages/django/db/backends/base/base.py", line 233, in _cursor
    self.ensure_connection()
  File "/usr/local/lib/python3.6/site-packages/django/db/backends/base/base.py", line 217, in ensure_connection
    self.connect()
  File "/usr/local/lib/python3.6/site-packages/django/db/utils.py", line 89, in __exit__
    raise dj_exc_value.with_traceback(traceback) from exc_value
  File "/usr/local/lib/python3.6/site-packages/django/db/backends/base/base.py", line 217, in ensure_connection
    self.connect()
  File "/usr/local/lib/python3.6/site-packages/django/db/backends/base/base.py", line 195, in connect
    self.connection = self.get_new_connection(conn_params)
  File "/usr/local/lib/python3.6/site-packages/django/db/backends/mysql/base.py", line 227, in get_new_connection
    return Database.connect(**conn_params)
  File "/usr/local/lib/python3.6/site-packages/pymysql/__init__.py", line 94, in Connect
    return Connection(*args, **kwargs)
  File "/usr/local/lib/python3.6/site-packages/pymysql/connections.py", line 325, in __init__
    self.connect()
  File "/usr/local/lib/python3.6/site-packages/pymysql/connections.py", line 630, in connect
    raise exc
django.db.utils.OperationalError: (2003, "Can't connect to MySQL server on 'crm.123medhk.com' ([Errno 111] Connection refused)")
/usr/local/lib/python3.6/site-packages/django/db/models/fields/__init__.py:1365: RuntimeWarning: DateTimeField EveryTask.send_finish_time received a naive datetime (2021-09-26 00:00:00) while time zone support is active.
  RuntimeWarning)
/usr/local/lib/python3.6/site-packages/django/db/models/fields/__init__.py:1365: RuntimeWarning: DateTimeField EveryTask.send_finish_time received a naive datetime (2021-09-29 00:00:00) while time zone support is active.
  RuntimeWarning)
/usr/local/lib/python3.6/site-packages/django/db/models/fields/__init__.py:1423: RuntimeWarning: DateTimeField EveryTask.send_finish_time received a naive datetime (2021-09-28 19:25:07.994315) while time zone support is active.
  RuntimeWarning)
/usr/local/lib/python3.6/site-packages/django/db/models/fields/__init__.py:1365: RuntimeWarning: DateTimeField EmailApply.next_time received a naive datetime (2021-09-27 00:00:00) while time zone support is active.
  RuntimeWarning)
/usr/local/lib/python3.6/site-packages/django/db/models/fields/__init__.py:1365: RuntimeWarning: DateTimeField EmailApply.next_time received a naive datetime (2021-09-28 00:00:00) while time zone support is active.
  RuntimeWarning)
/usr/local/lib/python3.6/site-packages/django/db/models/fields/__init__.py:1423: RuntimeWarning: DateTimeField EveryTask.send_finish_time received a naive datetime (2021-09-28 20:20:08.390432) while time zone support is active.
  RuntimeWarning)
Not Found: /.env
Not Found: /.env
Forbidden (CSRF cookie not set.): /
Not Found: /robots.txt
Not Found: /sitemap.xml
Not Found: /.well-known/security.txt
Not Found: /text4041632841619
Not Found: /HNAP1
Not Found: /sdk
Not Found: /evox/about
Not Found: /boaform/admin/formLogin
Not Found: /HNAP1/
Not Found: /robots.txt
Not Found: /.env
Not Found: /.env
Forbidden (CSRF cookie not set.): /
Not Found: /config/getuser
Not Found: /vendor/phpunit/phpunit/src/Util/PHP/eval-stdin.php
Not Found: /vendor/phpunit/phpunit/src/Util/PHP/eval-stdin.php
Not Found: /solr/admin/info/system
Not Found: /wp-content/plugins/wp-file-manager/readme.txt
Not Found: /api/jsonws/invoke
Not Found: /index.php
Not Found: /console/
Not Found: /Autodiscover/Autodiscover.xml
Not Found: /_ignition/execute-solution
Not Found: /.env
Forbidden (CSRF cookie not set.): /
Not Found: /boaform/admin/formLogin
Not Found: /.env
Forbidden (CSRF cookie not set.): /
Not Found: /.env
Forbidden (CSRF cookie not set.): /
Not Found: /boaform/admin/formLogin
Not Found: /config/getuser
Not Found: /setup.cgi
/usr/local/lib/python3.6/site-packages/django/db/models/fields/__init__.py:1365: RuntimeWarning: DateTimeField EveryTask.send_finish_time received a naive datetime (2021-09-27 00:00:00) while time zone support is active.
  RuntimeWarning)
/usr/local/lib/python3.6/site-packages/django/db/models/fields/__init__.py:1365: RuntimeWarning: DateTimeField EveryTask.send_finish_time received a naive datetime (2021-09-30 00:00:00) while time zone support is active.
  RuntimeWarning)
/usr/local/lib/python3.6/site-packages/django/db/models/fields/__init__.py:1365: RuntimeWarning: DateTimeField EmailApply.next_time received a naive datetime (2021-09-29 00:00:00) while time zone support is active.
  RuntimeWarning)
Not Found: /boaform/admin/formLogin
Not Found: /boaform/admin/formLogin
mysqldump: [Warning] Using a password on the command line interface can be insecure.
Not Found: /.env
Forbidden (CSRF cookie not set.): /
Not Found: /config/getuser
Not Found: /wp-includes/js/jquery/jquery.js
Not Found: /administrator/help/en-GB/toc.json
Not Found: /administrator/language/en-GB/install.xml
Not Found: /plugins/system/debug/debug.xml
Not Found: /administrator/
Not Found: /misc/ajax.js
Not Found: /admin/view/javascript/common.js
Not Found: /admin/includes/general.js
Not Found: /images/editor/separator.gif
Not Found: /js/header-rollup-554.js
Not Found: /vendor/phpunit/phpunit/build.xml
Not Found: /fckeditor/editor/filemanager/connectors/php/upload.php
Not Found: /.env
Not Found: /wp-admin/setup-config.php
Not Found: /wordpress/wp-admin/setup-config.php
Not Found: /wp/wp-admin/setup-config.php
Not Found: /blog/wp-admin/setup-config.php
Not Found: /test/wp-admin/setup-config.php
Not Found: /site/wp-admin/setup-config.php
Not Found: /.env
Forbidden (CSRF cookie not set.): /
Not Found: /boaform/admin/formLogin
Not Found: /sql/webdb/index.php
Not Found: /database/index.php
Not Found: /phpmyadmin2020/index.php
Not Found: /sql/sql/index.php
Not Found: /administrator/db/index.php
Not Found: /PMA2014/index.php
Not Found: /phpmyadmin2018/index.php
Not Found: /phpmyAdmin/index.php
Not Found: /pma2021/index.php
Not Found: /db/index.php
Not Found: /db/websql/index.php
Not Found: /db/webadmin/index.php
Not Found: /PMA2014/index.php
Not Found: /sql/phpmanager/index.php
Not Found: /pma2020/index.php
Not Found: /mysql/pma/index.php
Not Found: /phpMyAdmin-5.1.1/index.php
Not Found: /phpMyAdmin-5.1.1/index.php
Not Found: /.env
Forbidden (CSRF cookie not set.): /
mysqldump: [Warning] Using a password on the command line interface can be insecure.
Not Found: /boaform/admin/formLogin
/usr/local/lib/python3.6/site-packages/django/db/models/fields/__init__.py:1423: RuntimeWarning: DateTimeField EveryTask.send_finish_time received a naive datetime (2021-09-29 19:00:08.207620) while time zone support is active.
  RuntimeWarning)
Internal Server Error: /login/
Traceback (most recent call last):
  File "/usr/local/lib/python3.6/site-packages/django/core/handlers/exception.py", line 34, in inner
    response = get_response(request)
  File "/usr/local/lib/python3.6/site-packages/django/core/handlers/base.py", line 115, in _get_response
    response = self.process_exception_by_middleware(e, request)
  File "/usr/local/lib/python3.6/site-packages/django/core/handlers/base.py", line 113, in _get_response
    response = wrapped_callback(request, *callback_args, **callback_kwargs)
  File "/usr/local/lib/python3.6/site-packages/django/views/generic/base.py", line 71, in view
    return self.dispatch(request, *args, **kwargs)
  File "/usr/local/lib/python3.6/site-packages/django/views/generic/base.py", line 97, in dispatch
    return handler(request, *args, **kwargs)
  File "/root/SMSTask/Twilio/Appis/User/views.py", line 51, in post
    request.session['layout'] = settings.FUNC_LAYOUT
AttributeError: module 'Twilio.settings' has no attribute 'FUNC_LAYOUT'
Internal Server Error: /login/
Traceback (most recent call last):
  File "/usr/local/lib/python3.6/site-packages/django/core/handlers/exception.py", line 34, in inner
    response = get_response(request)
  File "/usr/local/lib/python3.6/site-packages/django/core/handlers/base.py", line 115, in _get_response
    response = self.process_exception_by_middleware(e, request)
  File "/usr/local/lib/python3.6/site-packages/django/core/handlers/base.py", line 113, in _get_response
    response = wrapped_callback(request, *callback_args, **callback_kwargs)
  File "/usr/local/lib/python3.6/site-packages/django/views/generic/base.py", line 71, in view
    return self.dispatch(request, *args, **kwargs)
  File "/usr/local/lib/python3.6/site-packages/django/views/generic/base.py", line 97, in dispatch
    return handler(request, *args, **kwargs)
  File "/root/SMSTask/Twilio/Appis/User/views.py", line 51, in post
    request.session['layout'] = settings.FUNC_LAYOUT
AttributeError: module 'Twilio.settings' has no attribute 'FUNC_LAYOUT'
Internal Server Error: /login/
Traceback (most recent call last):
  File "/usr/local/lib/python3.6/site-packages/django/core/handlers/exception.py", line 34, in inner
    response = get_response(request)
  File "/usr/local/lib/python3.6/site-packages/django/core/handlers/base.py", line 115, in _get_response
    response = self.process_exception_by_middleware(e, request)
  File "/usr/local/lib/python3.6/site-packages/django/core/handlers/base.py", line 113, in _get_response
    response = wrapped_callback(request, *callback_args, **callback_kwargs)
  File "/usr/local/lib/python3.6/site-packages/django/views/generic/base.py", line 71, in view
    return self.dispatch(request, *args, **kwargs)
  File "/usr/local/lib/python3.6/site-packages/django/views/generic/base.py", line 97, in dispatch
    return handler(request, *args, **kwargs)
  File "/root/SMSTask/Twilio/Appis/User/views.py", line 51, in post
    request.session['layout'] = settings.FUNC_LAYOUT
AttributeError: module 'Twilio.settings' has no attribute 'FUNC_LAYOUT'
Internal Server Error: /login/
Traceback (most recent call last):
  File "/usr/local/lib/python3.6/site-packages/django/core/handlers/exception.py", line 34, in inner
    response = get_response(request)
  File "/usr/local/lib/python3.6/site-packages/django/core/handlers/base.py", line 115, in _get_response
    response = self.process_exception_by_middleware(e, request)
  File "/usr/local/lib/python3.6/site-packages/django/core/handlers/base.py", line 113, in _get_response
    response = wrapped_callback(request, *callback_args, **callback_kwargs)
  File "/usr/local/lib/python3.6/site-packages/django/views/generic/base.py", line 71, in view
    return self.dispatch(request, *args, **kwargs)
  File "/usr/local/lib/python3.6/site-packages/django/views/generic/base.py", line 97, in dispatch
    return handler(request, *args, **kwargs)
  File "/root/SMSTask/Twilio/Appis/User/views.py", line 51, in post
    request.session['layout'] = settings.FUNC_LAYOUT
AttributeError: module 'Twilio.settings' has no attribute 'FUNC_LAYOUT'
[2021-09-29 11:36:22 +0000] [667] [INFO] Handling signal: term
[2021-09-29 19:36:22 +0800] [670] [INFO] Worker exiting (pid: 670)
[2021-09-29 11:36:23 +0000] [667] [INFO] Shutting down: Master
[2021-09-29 11:36:35 +0000] [668] [INFO] Starting gunicorn 20.0.4
[2021-09-29 11:36:35 +0000] [668] [INFO] Listening at: http://0.0.0.0:8000 (668)
[2021-09-29 11:36:35 +0000] [668] [INFO] Using worker: threads
[2021-09-29 11:36:35 +0000] [671] [INFO] Booting worker with pid: 671
/usr/local/lib/python3.6/site-packages/django/db/models/fields/__init__.py:1365: RuntimeWarning: DateTimeField EveryTask.send_finish_time received a naive datetime (2021-09-27 00:00:00) while time zone support is active.
  RuntimeWarning)
/usr/local/lib/python3.6/site-packages/django/db/models/fields/__init__.py:1365: RuntimeWarning: DateTimeField EveryTask.send_finish_time received a naive datetime (2021-09-30 00:00:00) while time zone support is active.
  RuntimeWarning)
/usr/local/lib/python3.6/site-packages/django/db/models/fields/__init__.py:1365: RuntimeWarning: DateTimeField EmailApply.next_time received a naive datetime (2021-09-28 00:00:00) while time zone support is active.
  RuntimeWarning)
/usr/local/lib/python3.6/site-packages/django/db/models/fields/__init__.py:1365: RuntimeWarning: DateTimeField EmailApply.next_time received a naive datetime (2021-09-29 00:00:00) while time zone support is active.
  RuntimeWarning)
Not Found: /contact/undefined
Not Found: /boaform/admin/formLogin
Not Found: /config/getuser
Not Found: /boaform/admin/formLogin
Not Found: /.env
Forbidden (CSRF cookie not set.): /
Not Found: /vendor/phpunit/phpunit/src/Util/PHP/eval-stdin.php
Not Found: /api/jsonws/invoke
Not Found: /vendor/phpunit/phpunit/src/Util/PHP/eval-stdin.php
Not Found: /solr/admin/info/system
Not Found: /index.php
Not Found: /console/
Not Found: /wp-content/plugins/wp-file-manager/readme.txt
Not Found: /Autodiscover/Autodiscover.xml
Not Found: /_ignition/execute-solution
Not Found: /boaform/admin/formLogin
Not Found: /aaa9
Not Found: /aab9
Not Found: /boaform/admin/formLogin
Not Found: /phpMyAdmin3/index.php
Not Found: /phpMyAdmin3/index.php
Not Found: /robots.txt
Not Found: /boaform/admin/formLogin
Not Found: /config/getuser
Not Found: /administrator/db/index.php
Not Found: /phpMyAdmin5/index.php
Not Found: /phpMyAdmin5/index.php
Not Found: /boaform/admin/formLogin
Not Found: /boaform/admin/formLogin
/usr/local/lib/python3.6/site-packages/django/db/models/fields/__init__.py:1365: RuntimeWarning: DateTimeField EveryTask.send_finish_time received a naive datetime (2021-09-28 00:00:00) while time zone support is active.
  RuntimeWarning)
/usr/local/lib/python3.6/site-packages/django/db/models/fields/__init__.py:1365: RuntimeWarning: DateTimeField EveryTask.send_finish_time received a naive datetime (2021-10-01 00:00:00) while time zone support is active.
  RuntimeWarning)
/usr/local/lib/python3.6/site-packages/django/db/models/fields/__init__.py:1423: RuntimeWarning: DateTimeField EveryTask.send_finish_time received a naive datetime (2021-09-30 10:01:44.873395) while time zone support is active.
  RuntimeWarning)
/usr/local/lib/python3.6/site-packages/django/db/models/fields/__init__.py:1365: RuntimeWarning: DateTimeField EmailApply.next_time received a naive datetime (2021-09-30 00:00:00) while time zone support is active.
  RuntimeWarning)
Not Found: /ReportServer
Not Found: /portal/redlion
Not Found: /hudson
mysqldump: [Warning] Using a password on the command line interface can be insecure.
Not Found: /boaform/admin/formLogin
Not Found: /robots.txt
Not Found: /sitemap.xml
Not Found: /.well-known/security.txt
Not Found: /config/getuser
Not Found: /.env
Forbidden (CSRF cookie not set.): /
Not Found: /config/getuser
mysqldump: [Warning] Using a password on the command line interface can be insecure.
Not Found: /api/jsonws/invoke
Not Found: /vendor/phpunit/phpunit/src/Util/PHP/eval-stdin.php
Not Found: /Autodiscover/Autodiscover.xml
Not Found: /_ignition/execute-solution
Not Found: /wp-content/plugins/wp-file-manager/readme.txt
Not Found: /solr/admin/info/system
Not Found: /index.php
Not Found: /console/
Not Found: /vendor/phpunit/phpunit/src/Util/PHP/eval-stdin.php
Not Found: /.env
Forbidden (CSRF cookie not set.): /
Not Found: /boaform/admin/formLogin
Not Found: /boaform/admin/formLogin
Not Found: /.git/config
Not Found: /setup.cgi
Not Found: /boaform/admin/formLogin
Not Found: /shell
Not Found: /config/getuser
Not Found: /boaform/admin/formLogin
Not Found: /system_api.php
Not Found: /c/version.js
Not Found: /streaming/clients_live.php
Not Found: /stalker_portal/c/version.js
Not Found: /stream/live.php
Not Found: /flu/403.html
Not Found: /config/getuser
Not Found: /boaform/admin/formLogin
Not Found: /.env
Forbidden (CSRF cookie not set.): /
/usr/local/lib/python3.6/site-packages/django/db/models/fields/__init__.py:1365: RuntimeWarning: DateTimeField EveryTask.send_finish_time received a naive datetime (2021-09-29 00:00:00) while time zone support is active.
  RuntimeWarning)
/usr/local/lib/python3.6/site-packages/django/db/models/fields/__init__.py:1365: RuntimeWarning: DateTimeField EveryTask.send_finish_time received a naive datetime (2021-10-02 00:00:00) while time zone support is active.
  RuntimeWarning)
/usr/local/lib/python3.6/site-packages/django/db/models/fields/__init__.py:1365: RuntimeWarning: DateTimeField EmailApply.next_time received a naive datetime (2021-10-01 00:00:00) while time zone support is active.
  RuntimeWarning)
Not Found: /config/getuser
Not Found: /db/db-admin/index.php
Not Found: /db/db-admin/index.php
Not Found: /PMA2018/index.php
Not Found: /admin/index.php
Not Found: /PMA2014/index.php
Not Found: /phpmyadmin2/index.php
Not Found: /mysql/pma/index.php
Not Found: /phpmyadmin2019/index.php
Not Found: /pma2014/index.php
Not Found: /mysql/pma/index.php
Not Found: /sql/phpmanager/index.php
Not Found: /sql/sql-admin/index.php
Not Found: /sql/phpmyadmin3/index.php
Not Found: /phpMyAdmin5/index.php
Not Found: /phpMyAdmin5/index.php
mysqldump: [Warning] Using a password on the command line interface can be insecure.
Not Found: /boaform/admin/formLogin
Not Found: /boaform/admin/formLogin
mysqldump: [Warning] Using a password on the command line interface can be insecure.
Not Found: /vendor/phpunit/phpunit/src/Util/PHP/eval-stdin.php
Not Found: /solr/admin/info/system
Not Found: /index.php
Not Found: /api/jsonws/invoke
Not Found: /Autodiscover/Autodiscover.xml
Not Found: /wp-content/plugins/wp-file-manager/readme.txt
Not Found: /console/
Not Found: /vendor/phpunit/phpunit/src/Util/PHP/eval-stdin.php
Not Found: /_ignition/execute-solution
Not Found: /.env
Forbidden (CSRF cookie not set.): /
Not Found: /boaform/admin/formLogin
Not Found: /config/getuser
Not Found: /config/getuser
Not Found: /boaform/admin/formLogin
Not Found: /pma/index.php
Not Found: /admin/index.php
Not Found: /phpmyadmin2/index.php
Not Found: /pma2019/index.php
Not Found: /phpMyAdmin-5.1.1-english/index.php
Not Found: /phpMyAdmin-5.1.1-english/index.php
Not Found: /boaform/admin/formLogin
Not Found: /.env
Forbidden (CSRF cookie not set.): /
Not Found: /config/getuser
Not Found: /config/getuser
Not Found: /phpmyadmin/
Not Found: /phpmyadmin/
Not Found: /config/getuser
Not Found: /config/getuser
Not Found: /boaform/admin/formLogin
Not Found: /config/getuser
Not Found: /.env
Forbidden (CSRF cookie not set.): /
Not Found: /config/getuser
Not Found: /.env
Forbidden (CSRF cookie not set.): /
Not Found: /config/getuser
/usr/local/lib/python3.6/site-packages/django/db/models/fields/__init__.py:1365: RuntimeWarning: DateTimeField EveryTask.send_finish_time received a naive datetime (2021-10-03 00:00:00) while time zone support is active.
  RuntimeWarning)
/usr/local/lib/python3.6/site-packages/django/db/models/fields/__init__.py:1365: RuntimeWarning: DateTimeField EmailApply.next_time received a naive datetime (2021-10-02 00:00:00) while time zone support is active.
  RuntimeWarning)
Not Found: /config/getuser
Not Found: /manager/html
Not Found: /_ignition/execute-solution
Not Found: /api/jsonws/invoke
Not Found: /vendor/phpunit/phpunit/src/Util/PHP/eval-stdin.php
Not Found: /console/
Not Found: /Autodiscover/Autodiscover.xml
Not Found: /wp-content/plugins/wp-file-manager/readme.txt
Not Found: /solr/admin/info/system
Not Found: /vendor/phpunit/phpunit/src/Util/PHP/eval-stdin.php
Not Found: /index.php
Not Found: /boaform/admin/formLogin
mysqldump: [Warning] Using a password on the command line interface can be insecure.
Not Found: /boaform/admin/formLogin
Not Found: /config/getuser
mysqldump: [Warning] Using a password on the command line interface can be insecure.
/usr/local/lib/python3.6/site-packages/django/db/models/fields/__init__.py:1423: RuntimeWarning: DateTimeField EveryTask.send_finish_time received a naive datetime (2021-10-02 16:12:03) while time zone support is active.
  RuntimeWarning)
/usr/local/lib/python3.6/site-packages/django/db/models/fields/__init__.py:1423: RuntimeWarning: DateTimeField EveryTask.send_finish_time received a naive datetime (2021-10-02 16:12:04.957301) while time zone support is active.
  RuntimeWarning)
/usr/local/lib/python3.6/site-packages/django/db/models/fields/__init__.py:1423: RuntimeWarning: DateTimeField EveryTask.send_finish_time received a naive datetime (2021-12-01 16:12:04) while time zone support is active.
  RuntimeWarning)
/usr/local/lib/python3.6/site-packages/django/db/models/fields/__init__.py:1423: RuntimeWarning: DateTimeField EveryTask.send_finish_time received a naive datetime (2022-03-31 16:12:04) while time zone support is active.
  RuntimeWarning)
Not Found: /config/getuser
Not Found: /.env
/usr/local/lib/python3.6/site-packages/django/db/models/fields/__init__.py:1423: RuntimeWarning: DateTimeField EveryTask.send_finish_time received a naive datetime (2021-10-02 17:03:30) while time zone support is active.
  RuntimeWarning)
/usr/local/lib/python3.6/site-packages/django/db/models/fields/__init__.py:1423: RuntimeWarning: DateTimeField EveryTask.send_finish_time received a naive datetime (2021-10-02 17:03:32.200971) while time zone support is active.
  RuntimeWarning)
/usr/local/lib/python3.6/site-packages/django/db/models/fields/__init__.py:1423: RuntimeWarning: DateTimeField EveryTask.send_finish_time received a naive datetime (2021-12-01 17:03:32) while time zone support is active.
  RuntimeWarning)
/usr/local/lib/python3.6/site-packages/django/db/models/fields/__init__.py:1423: RuntimeWarning: DateTimeField EveryTask.send_finish_time received a naive datetime (2022-03-31 17:03:32) while time zone support is active.
  RuntimeWarning)
Not Found: /.env
Forbidden (CSRF cookie not set.): /
Not Found: /config/getuser
Not Found: /stalker_portal/server/tools/auth_simple.php
Not Found: /boaform/admin/formLogin
Not Found: /boaform/admin/formLogin
Not Found: /config/getuser
Not Found: /config/getuser
Not Found: /boaform/admin/formLogin
Not Found: /login.action
Not Found: /robots.txt
Not Found: /sitemap.xml
Not Found: /robots.txt
Not Found: /sitemap.xml
Not Found: /.well-known/security.txt
Not Found: /.env
Forbidden (CSRF cookie not set.): /
Not Found: /w00tw00t.at.blackhats.romanian.anti-sec:)
Not Found: /phpMyAdmin/scripts/setup.php
Not Found: /.env
Forbidden (CSRF cookie not set.): /
Not Found: /boaform/admin/formLogin
Not Found: /robots.txt
Not Found: /h5/
Forbidden (CSRF token missing or incorrect.): /
Forbidden (CSRF token missing or incorrect.): /
Not Found: /homes/
Not Found: /kefu.php
Not Found: /homes/
Not Found: /api/apps
Not Found: /config.js
Not Found: /getLocale
Not Found: /user/Login
Not Found: /js/home.js
Not Found: /style.css
Not Found: /common.js
Not Found: /api/linkPF
Not Found: /Css/Hm.css
Not Found: /admin/index
Not Found: /css/app.css
Not Found: /m/allticker/1
Not Found: /fePublicInfo/
Not Found: /nyyh/game.css
Not Found: /langConfig.js
Not Found: /css/style.css
Not Found: /im/in/GetUuid
Not Found: /im/App/config
Not Found: /img/close.png
Not Found: /api/contactWay
Not Found: /proxy/settings
Not Found: /app/js/base.js
Not Found: /m/ticker/usdtqc
Not Found: /anquan/qgga.asp
Not Found: /home/main/login
Not Found: /api/index/index
Not Found: /user/allroleinfo
Not Found: /banner.do
Not Found: /verification.asp
Not Found: /index/api/config
Not Found: /script/public.js
Not Found: /Home/Bind/binding
Not Found: /appxz/index.html
Not Found: /Home/Index/ajaxTJ
Not Found: /csjs/bankCheck.js
Not Found: /css/nsc/reset.css
Not Found: /Home/Get/getJnd28
Not Found: /skin/js/common.js
Not Found: /JS/loginstatus.js
Not Found: /legal/currency/set
Not Found: /Pc/Lang/index.html
Not Found: /views/home/home.js
Not Found: /api/v1/member/kefu
Not Found: /manager/js/left.js
Not Found: /public/img/cz1.png
Not Found: /wap/banner/details
Not Found: /login/kefuxian.mvc
Not Found: /files/pub_reset.css
Not Found: /room/script/face.js
Not Found: /assets/js/dmshub.js
Not Found: /Public/js/common.js
Not Found: /api/index/webconfig
Not Found: /room/getRoomBangFans
Not Found: /Promotions/list.mvc
Not Found: /index/login/register
Not Found: /api/Index/getLottery
Not Found: /api/v1/borrowxx.html
Not Found: /api/common/getConfig
Not Found: /Content/Wap/base.css
Not Found: /api/user/mobilelogin
Not Found: /api/index/grailindex
Not Found: /data/json/config.json
Not Found: /jiaoyimao/default.css
Not Found: /cscpLoginWeb/app/home
Not Found: /Public/Home/js/cls.js
Not Found: /lanren/css/global.css
Not Found: /css/view/main/goin.css
Not Found: /Public/Home/js/game.js
Not Found: /xianyu/index/setp1.html
Not Found: /Public/css/errorCss.css
Not Found: /css/view/main/style.css
Not Found: /ajax
Not Found: /zz2/address.php
Not Found: /member/js/lang_zh_CN.js
Not Found: /api/customerServiceLink
Not Found: /Public/Home/js/common.js
Not Found: /guess/list.php
Not Found: /client/api/findFreeTrade
Not Found: /assets/app-manifest.json
Not Found: /s_api/basic/download/info
Not Found: /Public/home/js/fukuang.js
Not Found: /Content/css/wzwstylel.css
Not Found: /app/common/getRegisterSet
Not Found: /Public/Wchat/css/index.css
Not Found: /template/920ka/css/lsy.css
Not Found: /template/tmp1/js/common.js
Not Found: /public/h5static/js/main.js
Not Found: /api/currency/quotation_new
Not Found: /Public/mobile/js/config.js
Not Found: /Template/Mobile/js/main.js
Not Found: /index.php/Wap/Api/getBanner
Not Found: /market/market-ws/iframe.html
Not Found: /config.php
Not Found: /api/system/system/config/get
Not Found: /Public/uploads/web/step1.png
Not Found: /mobile/v3/appSuperDownload.do
Not Found: /api/web/user/getIndexData.php
Not Found: /public/web/css/add//index.css
Not Found: /melody/api/v1/pageconfig/list
Not Found: /getConfig/getArticle.do
Not Found: /cscpLoginWeb/scripts/public.js
Not Found: /Public/home/common/js/index.js
Not Found: /public/appapi/images/error.jpg
Not Found: /index.php/api/other/appSetting
Not Found: /assets/room/css/room_mobile.css
Not Found: /api/mobile/checkStrategyHistory
Not Found: /infe/rest/flash/getServerIP.json
Not Found: /index/Mobile/fenshi
Not Found: /Public/Home/images/game/pk10.png
Not Found: /wap/trading/get_newallorder_ajax
Not Found: /api/public/
Not Found: /base/exchange_index/changepwdfirst
Not Found: /assets/extension/market/css/mt4.css
Not Found: /assets/dist/static/js/vendor_prod.js
Not Found: /public/admin.php/api/index/loansList
Not Found: /Templates/user/finance/css/userPay.css
Not Found: /api/stock/getSingleStock.do
Not Found: /index.php
Not Found: /public/static/home/js/moblie/login.js
Not Found: /base/exchange_article/index/classid/1/id/1
Not Found: /Public/Home/ecshe_css/main.css
Not Found: /common/template/lottery/lecai/css/style.css
Not Found: /Public/Mobile/ecshe_css/wapmain.css
Not Found: /infe/rest/fig/advertise/common.json
Not Found: /client/api/findConfigByKey
Not Found: /api/v/index/queryOfficePage
Not Found: /ipl/app/flash/publicbmw/ball/FigLeaf.js
Not Found: /json/configs/permanent/permanent-lottery-config-list.json
Not Found: /getConfig/listPopFrame.do
Not Found: /api/product/topRank
Not Found: /api/v1/about
Not Found: /api/config-init
Not Found: /public/static/css/denglu.css
Not Found: /auth/oauth/token
Not Found: /api/jsonws/invoke
Not Found: /vendor/phpunit/phpunit/src/Util/PHP/eval-stdin.php
Not Found: /vendor/phpunit/phpunit/src/Util/PHP/eval-stdin.php
Not Found: /index.php
Not Found: /console/
Not Found: /solr/admin/info/system
Not Found: /_ignition/execute-solution
Not Found: /wp-content/plugins/wp-file-manager/readme.txt
Not Found: /Autodiscover/Autodiscover.xml
Not Found: /config/getuser
Not Found: /c/
Not Found: /404/index.html
Not Found: /404/index.html
Not Found: /config/getuser
Not Found: /.env
Forbidden (CSRF cookie not set.): /
Not Found: /.env
Forbidden (CSRF cookie not set.): /
Not Found: /core/.env
Forbidden (CSRF cookie not set.): /
Not Found: /app/.env
Forbidden (CSRF cookie not set.): /
Not Found: /public/.env
Forbidden (CSRF cookie not set.): /
/usr/local/lib/python3.6/site-packages/django/db/models/fields/__init__.py:1365: RuntimeWarning: DateTimeField EveryTask.send_finish_time received a naive datetime (2021-10-04 00:00:00) while time zone support is active.
  RuntimeWarning)
/usr/local/lib/python3.6/site-packages/django/db/models/fields/__init__.py:1365: RuntimeWarning: DateTimeField EmailApply.next_time received a naive datetime (2021-10-03 00:00:00) while time zone support is active.
  RuntimeWarning)
Not Found: /portal/redlion
Not Found: /fuN3
Not Found: /config/getuser
Not Found: /config/getuser
Not Found: /hudson
Not Found: /config/getuser
mysqldump: [Warning] Using a password on the command line interface can be insecure.
Not Found: /config/getuser
Not Found: /.env
Forbidden (CSRF cookie not set.): /
mysqldump: [Warning] Using a password on the command line interface can be insecure.
Not Found: /boaform/admin/formLogin
Not Found: /boaform/admin/formLogin
Not Found: /boaform/admin/formLogin
Not Found: /shell
Not Found: /_ignition/execute-solution
Not Found: /console/
Not Found: /index.php
Not Found: /solr/admin/info/system
Not Found: /api/jsonws/invoke
Not Found: /wp-content/plugins/wp-file-manager/readme.txt
Not Found: /vendor/phpunit/phpunit/src/Util/PHP/eval-stdin.php
Not Found: /Autodiscover/Autodiscover.xml
Not Found: /vendor/phpunit/phpunit/src/Util/PHP/eval-stdin.php
Not Found: /config/getuser
Not Found: /config/getuser
Not Found: /boaform/admin/formLogin
Not Found: /config/getuser
Not Found: /.env
Forbidden (CSRF cookie not set.): /
Not Found: /manager/text/list
Not Found: /config/getuser
Not Found: /boaform/admin/formLogin
Not Found: /manager/html
Not Found: /boaform/admin/formLogin
Not Found: /.env
Forbidden (CSRF cookie not set.): /
Not Found: /config/getuser
Not Found: /config/getuser
/usr/local/lib/python3.6/site-packages/django/db/models/fields/__init__.py:1365: RuntimeWarning: DateTimeField EveryTask.send_finish_time received a naive datetime (2021-10-05 00:00:00) while time zone support is active.
  RuntimeWarning)
/usr/local/lib/python3.6/site-packages/django/db/models/fields/__init__.py:1365: RuntimeWarning: DateTimeField EmailApply.next_time received a naive datetime (2021-10-04 00:00:00) while time zone support is active.
  RuntimeWarning)
Not Found: /Portal/Portal.mwsl
Not Found: /xY7T
Not Found: /nmaplowercheck1633317710
Not Found: /owa/auth/x.js
Not Found: /.git/HEAD
Not Found: /sdk
Not Found: /nmaplowercheck1633317715
Not Found: /CSS/Miniweb.css
Not Found: /main.cfm
Not Found: /scripts/WPnBr.dll
Not Found: /Portal0000.htm
mysqldump: [Warning] Using a password on the command line interface can be insecure.
Not Found: /boaform/admin/formLogin
Not Found: /api/jsonws/invoke
Not Found: /vendor/phpunit/phpunit/src/Util/PHP/eval-stdin.php
Not Found: /vendor/phpunit/phpunit/src/Util/PHP/eval-stdin.php
Not Found: /solr/admin/info/system
Not Found: /index.php
Not Found: /wp-content/plugins/wp-file-manager/readme.txt
Not Found: /console/
Not Found: /Autodiscover/Autodiscover.xml
Not Found: /_ignition/execute-solution
Not Found: /boaform/admin/formLogin
mysqldump: [Warning] Using a password on the command line interface can be insecure.
Not Found: /.env
Not Found: /shell
Not Found: /boaform/admin/formLogin
Not Found: /.env
Forbidden (CSRF cookie not set.): /
Not Found: /boaform/admin/formLogin
Not Found: /lixuan.php
Not Found: /lixuan.php
Not Found: /boaform/admin/formLogin
Not Found: /config/getuser
Not Found: /boaform/admin/formLogin
Not Found: /boaform/admin/formLogin
Not Found: /config/getuser
/usr/local/lib/python3.6/site-packages/django/db/models/fields/__init__.py:1365: RuntimeWarning: DateTimeField EveryTask.send_finish_time received a naive datetime (2021-10-06 00:00:00) while time zone support is active.
  RuntimeWarning)
/usr/local/lib/python3.6/site-packages/django/db/models/fields/__init__.py:1365: RuntimeWarning: DateTimeField EmailApply.next_time received a naive datetime (2021-10-05 00:00:00) while time zone support is active.
  RuntimeWarning)
Not Found: /Telerik.Web.UI.WebResource.axd
Not Found: /.env
mysqldump: [Warning] Using a password on the command line interface can be insecure.
Not Found: /.env
Forbidden (CSRF cookie not set.): /
Not Found: /vendor/phpunit/phpunit/src/Util/PHP/eval-stdin.php
Not Found: /api/jsonws/invoke
Not Found: /solr/admin/info/system
Not Found: /index.php
Not Found: /console/
Not Found: /_ignition/execute-solution
Not Found: /vendor/phpunit/phpunit/src/Util/PHP/eval-stdin.php
Not Found: /Autodiscover/Autodiscover.xml
Not Found: /wp-content/plugins/wp-file-manager/readme.txt
Not Found: /boaform/admin/formLogin
mysqldump: [Warning] Using a password on the command line interface can be insecure.
Not Found: /.env
Forbidden (CSRF cookie not set.): /
Not Found: /config/getuser
Not Found: /boaform/admin/formLogin
Not Found: /setup.cgi
Not Found: /config/getuser
Not Found: /setup.cgi
Not Found: /boaform/admin/formLogin
Not Found: /boaform/admin/formLogin
Not Found: /config/getuser
Not Found: /shell
Not Found: /boaform/admin/formLogin
Not Found: /config/getuser
Not Found: /boaform/admin/formLogin
Not Found: /config/getuser
Not Found: /vendor/phpunit/phpunit/src/Util/PHP/eval-stdin.php
Not Found: /api/jsonws/invoke
Not Found: /vendor/phpunit/phpunit/src/Util/PHP/eval-stdin.php
Not Found: /solr/admin/info/system
Not Found: /index.php
Not Found: /wp-content/plugins/wp-file-manager/readme.txt
Not Found: /console/
Not Found: /Autodiscover/Autodiscover.xml
Not Found: /_ignition/execute-solution
Not Found: /config/getuser
Not Found: /boaform/admin/formLogin
Not Found: /images/logo-tiny.png
Not Found: /config/getuser
Not Found: /boaform/admin/formLogin
/usr/local/lib/python3.6/site-packages/django/db/models/fields/__init__.py:1365: RuntimeWarning: DateTimeField EveryTask.send_finish_time received a naive datetime (2021-10-07 00:00:00) while time zone support is active.
  RuntimeWarning)
/usr/local/lib/python3.6/site-packages/django/db/models/fields/__init__.py:1365: RuntimeWarning: DateTimeField EmailApply.next_time received a naive datetime (2021-10-06 00:00:00) while time zone support is active.
  RuntimeWarning)
Not Found: /portal/redlion
Not Found: /actuator/health
Not Found: /hudson
Not Found: /boaform/admin/formLogin
Not Found: /boaform/admin/formLogin
Not Found: /config/getuser
mysqldump: [Warning] Using a password on the command line interface can be insecure.
Not Found: /setup.cgi
Not Found: /boaform/admin/formLogin
Not Found: /shell
/usr/local/lib/python3.6/site-packages/django/db/models/fields/__init__.py:1423: RuntimeWarning: DateTimeField EveryTask.send_finish_time received a naive datetime (2021-10-06 15:44:03) while time zone support is active.
  RuntimeWarning)
/usr/local/lib/python3.6/site-packages/django/db/models/fields/__init__.py:1423: RuntimeWarning: DateTimeField EveryTask.send_finish_time received a naive datetime (2021-10-06 15:44:04.309938) while time zone support is active.
  RuntimeWarning)
/usr/local/lib/python3.6/site-packages/django/db/models/fields/__init__.py:1423: RuntimeWarning: DateTimeField EveryTask.send_finish_time received a naive datetime (2021-12-05 15:44:04) while time zone support is active.
  RuntimeWarning)
/usr/local/lib/python3.6/site-packages/django/db/models/fields/__init__.py:1423: RuntimeWarning: DateTimeField EveryTask.send_finish_time received a naive datetime (2022-04-04 15:44:04) while time zone support is active.
  RuntimeWarning)
mysqldump: [Warning] Using a password on the command line interface can be insecure.
Not Found: /.DS_Store
Not Found: /server-status
Not Found: /config.json
Not Found: /GponForm/diag_Form
Not Found: /.env
Forbidden (CSRF cookie not set.): /
Not Found: /boaform/admin/formLogin
Not Found: /boaform/admin/formLogin
Not Found: /.env
Not Found: /.env
Forbidden (CSRF cookie not set.): /
Not Found: /config/getuser
Not Found: /config/getuser
Not Found: /boaform/admin/formLogin
Not Found: /fuN3
Not Found: /boaform/admin/formLogin
Not Found: /phpmyadmin/index.php
Not Found: /config/getuser
Not Found: /vendor/phpunit/phpunit/src/Util/PHP/eval-stdin.php
Not Found: /api/jsonws/invoke
Not Found: /vendor/phpunit/phpunit/src/Util/PHP/eval-stdin.php
Not Found: /solr/admin/info/system
Not Found: /index.php
Not Found: /wp-content/plugins/wp-file-manager/readme.txt
Not Found: /console/
Not Found: /Autodiscover/Autodiscover.xml
Not Found: /_ignition/execute-solution
Not Found: /solr/
Not Found: /wp-includes/wlwmanifest.xml
Not Found: /xmlrpc.php
Not Found: /blog/wp-includes/wlwmanifest.xml
Not Found: /web/wp-includes/wlwmanifest.xml
Not Found: /wordpress/wp-includes/wlwmanifest.xml
Not Found: /website/wp-includes/wlwmanifest.xml
Not Found: /wp/wp-includes/wlwmanifest.xml
Not Found: /news/wp-includes/wlwmanifest.xml
Not Found: /2018/wp-includes/wlwmanifest.xml
Not Found: /2019/wp-includes/wlwmanifest.xml
Not Found: /shop/wp-includes/wlwmanifest.xml
Not Found: /wp1/wp-includes/wlwmanifest.xml
Not Found: /test/wp-includes/wlwmanifest.xml
Not Found: /media/wp-includes/wlwmanifest.xml
Not Found: /wp2/wp-includes/wlwmanifest.xml
Not Found: /site/wp-includes/wlwmanifest.xml
Not Found: /cms/wp-includes/wlwmanifest.xml
Not Found: /sito/wp-includes/wlwmanifest.xml
Not Found: /config/getuser
Not Found: /boaform/admin/formLogin
Not Found: /boaform/admin/formLogin
Not Found: /.env
Forbidden (CSRF cookie not set.): /
/usr/local/lib/python3.6/site-packages/django/db/models/fields/__init__.py:1365: RuntimeWarning: DateTimeField EveryTask.send_finish_time received a naive datetime (2021-10-08 00:00:00) while time zone support is active.
  RuntimeWarning)
/usr/local/lib/python3.6/site-packages/django/db/models/fields/__init__.py:1365: RuntimeWarning: DateTimeField EmailApply.next_time received a naive datetime (2021-10-07 00:00:00) while time zone support is active.
  RuntimeWarning)
Not Found: /config/getuser
Not Found: /ReportServer
Not Found: /phpmyadmin/
Not Found: /.env
